<?xml version="1.0" ?>
<!-- =================================================================================== -->
<!-- |    This document was autogenerated by xacro from moonbot01.urdf.xacro           | -->
<!-- |    EDITING THIS FILE BY HAND IS NOT RECOMMENDED                                 | -->
<!-- =================================================================================== -->
<robot name="moonbot01">
  <!-- link rviz colors -->
  <material name="White">
    <color rgba="1 1 1 1"/>
  </material>
  <material name="Black">
    <color rgba="0 0 0 1"/>
  </material>
  <!-- <xacro:include filename="$(find moonbot_description)/urdf/yonaka_0722/common_gazebo.xacro"/> -->
  <!-- foot -->
  <!-- foot -->
  <ros2_control name="IsaacSystem" type="system">
    <hardware>
      <plugin>topic_based_ros2_control/TopicBasedSystem</plugin>
      <param name="joint_commands_topic">/Isaac/joint_command</param>
      <param name="joint_states_topic">/Isaac/joint_states</param>
      <param name="sum_wrapped_joint_states">true</param>
      <param name="use_initial_states_as_initial_commands">false</param>
      <param name="wait_for_reaching_initial_values">true</param>
    </hardware>
    <joint name="left_arm_joint1">
      <command_interface name="position">
        <param name="min">-0.2617993877991494</param>
        <param name="max">3.141592653589793</param>
      </command_interface>
      <state_interface name="position">
        <!-- Set initial joint position -->
        <param name="initial_value">3.141592653589793</param>
      </state_interface>
      <state_interface name="velocity"/>
      <state_interface name="effort"/>
    </joint>
    <joint name="left_arm_joint2">
      <command_interface name="position">
        <param name="min">-2.6179938779914944</param>
        <param name="max">2.6179938779914944</param>
      </command_interface>
      <state_interface name="position">
        <!-- Set initial joint position -->
        <param name="initial_value">1.047</param>
      </state_interface>
      <state_interface name="velocity"/>
      <state_interface name="effort"/>
    </joint>
    <joint name="left_arm_joint3">
      <command_interface name="position">
        <param name="min">-2.6179938779914944</param>
        <param name="max">2.6179938779914944</param>
      </command_interface>
      <state_interface name="position">
        <!-- Set initial joint position -->
        <param name="initial_value">-2.356</param>
      </state_interface>
      <state_interface name="velocity"/>
      <state_interface name="effort"/>
    </joint>
    <joint name="left_arm_joint4">
      <command_interface name="position">
        <param name="min">-6.283185307179586</param>
        <param name="max">6.283185307179586</param>
      </command_interface>
      <state_interface name="position">
        <!-- Set initial joint position -->
        <param name="initial_value">3.141592653589793</param>
      </state_interface>
      <state_interface name="velocity"/>
      <state_interface name="effort"/>
    </joint>
    <joint name="left_arm_joint5">
      <command_interface name="position">
        <param name="min">-0.5235987755982988</param>
        <param name="max">0.5235987755982988</param>
      </command_interface>
      <state_interface name="position">
        <!-- Set initial joint position -->
        <param name="initial_value">0.0</param>
      </state_interface>
      <state_interface name="velocity"/>
      <state_interface name="effort"/>
    </joint>
    <joint name="left_arm_joint6">
      <command_interface name="position">
        <param name="min">-1.5707963267948966</param>
        <param name="max">1.5707963267948966</param>
      </command_interface>
      <state_interface name="position">
        <!-- Set initial joint position -->
        <param name="initial_value">0.0</param>
      </state_interface>
      <state_interface name="velocity"/>
      <state_interface name="effort"/>
    </joint>
    <joint name="right_arm_joint1">
      <command_interface name="position">
        <param name="min">-0.2617993877991494</param>
        <param name="max">3.141592653589793</param>
      </command_interface>
      <state_interface name="position">
        <!-- Set initial joint position -->
        <param name="initial_value">-3.141592653589793</param>
      </state_interface>
      <state_interface name="velocity"/>
      <state_interface name="effort"/>
    </joint>
    <joint name="right_arm_joint2">
      <command_interface name="position">
        <param name="min">-2.6179938779914944</param>
        <param name="max">2.6179938779914944</param>
      </command_interface>
      <state_interface name="position">
        <!-- Set initial joint position -->
        <param name="initial_value">1.047</param>
      </state_interface>
      <state_interface name="velocity"/>
      <state_interface name="effort"/>
    </joint>
    <joint name="right_arm_joint3">
      <command_interface name="position">
        <param name="min">-2.6179938779914944</param>
        <param name="max">2.6179938779914944</param>
      </command_interface>
      <state_interface name="position">
        <!-- Set initial joint position -->
        <param name="initial_value">-2.356</param>
      </state_interface>
      <state_interface name="velocity"/>
      <state_interface name="effort"/>
    </joint>
    <joint name="right_arm_joint4">
      <command_interface name="position">
        <param name="min">-6.283185307179586</param>
        <param name="max">6.283185307179586</param>
      </command_interface>
      <state_interface name="position">
        <!-- Set initial joint position -->
        <param name="initial_value">3.141592653589793</param>
      </state_interface>
      <state_interface name="velocity"/>
      <state_interface name="effort"/>
    </joint>
    <joint name="right_arm_joint5">
      <command_interface name="position">
        <param name="min">-0.5235987755982988</param>
        <param name="max">0.5235987755982988</param>
      </command_interface>
      <state_interface name="position">
        <!-- Set initial joint position -->
        <param name="initial_value">0.0</param>
      </state_interface>
      <state_interface name="velocity"/>
      <state_interface name="effort"/>
    </joint>
    <joint name="right_arm_joint6">
      <command_interface name="position">
        <param name="min">-1.5707963267948966</param>
        <param name="max">1.5707963267948966</param>
      </command_interface>
      <state_interface name="position">
        <!-- Set initial joint position -->
        <param name="initial_value">0.0</param>
      </state_interface>
      <state_interface name="velocity"/>
      <state_interface name="effort"/>
    </joint>
    <joint name="f_left_leg_joint1">
      <command_interface name="position">
        <param name="min">-1.5707963267948966</param>
        <param name="max">1.5707963267948966</param>
      </command_interface>
      <state_interface name="position">
        <!-- Set initial joint position -->
        <param name="initial_value">0.0</param>
      </state_interface>
      <state_interface name="velocity"/>
      <state_interface name="effort"/>
    </joint>
    <joint name="f_left_leg_joint2">
      <command_interface name="position">
        <param name="min">-2.6179938779914944</param>
        <param name="max">0.17453292519943295</param>
      </command_interface>
      <state_interface name="position">
        <!-- Set initial joint position -->
        <param name="initial_value">-0.96</param>
      </state_interface>
      <state_interface name="velocity"/>
      <state_interface name="effort"/>
    </joint>
    <joint name="f_left_leg_joint3">
      <command_interface name="position">
        <param name="min">-2.792526803190927</param>
        <param name="max">2.0943951023931953</param>
      </command_interface>
      <state_interface name="position">
        <!-- Set initial joint position -->
        <param name="initial_value">1.017</param>
      </state_interface>
      <state_interface name="velocity"/>
      <state_interface name="effort"/>
    </joint>
    <joint name="f_right_leg_joint1">
      <command_interface name="position">
        <param name="min">-1.5707963267948966</param>
        <param name="max">1.5707963267948966</param>
      </command_interface>
      <state_interface name="position">
        <!-- Set initial joint position -->
        <param name="initial_value">0.0</param>
      </state_interface>
      <state_interface name="velocity"/>
      <state_interface name="effort"/>
    </joint>
    <joint name="f_right_leg_joint2">
      <command_interface name="position">
        <param name="min">-2.6179938779914944</param>
        <param name="max">0.17453292519943295</param>
      </command_interface>
      <state_interface name="position">
        <!-- Set initial joint position -->
        <param name="initial_value">-0.96</param>
      </state_interface>
      <state_interface name="velocity"/>
      <state_interface name="effort"/>
    </joint>
    <joint name="f_right_leg_joint3">
      <command_interface name="position">
        <param name="min">-2.792526803190927</param>
        <param name="max">2.0943951023931953</param>
      </command_interface>
      <state_interface name="position">
        <!-- Set initial joint position -->
        <param name="initial_value">1.017</param>
      </state_interface>
      <state_interface name="velocity"/>
      <state_interface name="effort"/>
    </joint>
    <joint name="b_left_leg_joint1">
      <command_interface name="position">
        <param name="min">-1.5707963267948966</param>
        <param name="max">1.5707963267948966</param>
      </command_interface>
      <state_interface name="position">
        <!-- Set initial joint position -->
        <param name="initial_value">0.0</param>
      </state_interface>
      <state_interface name="velocity"/>
      <state_interface name="effort"/>
    </joint>
    <joint name="b_left_leg_joint2">
      <command_interface name="position">
        <param name="min">-2.6179938779914944</param>
        <param name="max">0.17453292519943295</param>
      </command_interface>
      <state_interface name="position">
        <!-- Set initial joint position -->
        <param name="initial_value">-0.96</param>
      </state_interface>
      <state_interface name="velocity"/>
      <state_interface name="effort"/>
    </joint>
    <joint name="b_left_leg_joint3">
      <command_interface name="position">
        <param name="min">-2.792526803190927</param>
        <param name="max">2.0943951023931953</param>
      </command_interface>
      <state_interface name="position">
        <!-- Set initial joint position -->
        <param name="initial_value">1.017</param>
      </state_interface>
      <state_interface name="velocity"/>
      <state_interface name="effort"/>
    </joint>
    <joint name="b_right_leg_joint1">
      <command_interface name="position">
        <param name="min">-1.5707963267948966</param>
        <param name="max">1.5707963267948966</param>
      </command_interface>
      <state_interface name="position">
        <!-- Set initial joint position -->
        <param name="initial_value">0.0</param>
      </state_interface>
      <state_interface name="velocity"/>
      <state_interface name="effort"/>
    </joint>
    <joint name="b_right_leg_joint2">
      <command_interface name="position">
        <param name="min">-2.6179938779914944</param>
        <param name="max">0.17453292519943295</param>
      </command_interface>
      <state_interface name="position">
        <!-- Set initial joint position -->
        <param name="initial_value">-0.96</param>
      </state_interface>
      <state_interface name="velocity"/>
      <state_interface name="effort"/>
    </joint>
    <joint name="b_right_leg_joint3">
      <command_interface name="position">
        <param name="min">-2.792526803190927</param>
        <param name="max">2.0943951023931953</param>
      </command_interface>
      <state_interface name="position">
        <!-- Set initial joint position -->
        <param name="initial_value">1.017</param>
      </state_interface>
      <state_interface name="velocity"/>
      <state_interface name="effort"/>
    </joint>
  </ros2_control>
  <!-- Gazebo's ros2_control plugin  -->
  <!-- <gazebo>
        <plugin name="gazebo_ros2_control" filename="libgazebo_ros2_control.so">
            <robot_sim_type>gazebo_ros2_control/GazeboSystem</robot_sim_type>
            <robot_param>robot_description</robot_param>
            <robot_param_node>robot_state_publisher_node</robot_param_node>
            <parameters>$(find moonbot_description)/config/jtc01.yaml</parameters>
        </plugin>
    </gazebo> -->
  <!-- base link -->
  <link name="base_link"/>
  <!-- body joint -->
  <joint name="base_to_body" type="fixed">
    <origin rpy="0 0 0" xyz="0 0 0"/>
    <parent link="base_link"/>
    <child link="body_link"/>
  </joint>
  <link name="body_link">
    <visual>
      <origin rpy="0 0 0" xyz="0 0 0"/>
      <material name="White"/>
      <geometry>
        <mesh filename="package://moonbot_description/meshesY/BASE.STL" scale="0.001 0.001 0.001"/>
      </geometry>
    </visual>
    <collision>
      <origin rpy="0 0 0" xyz="0 0 0"/>
      <geometry>
        <mesh filename="package://moonbot_description/meshesY/BASE.STL" scale="0.001 0.001 0.001"/>
      </geometry>
    </collision>
    <inertial>
      <origin rpy="0 0 0" xyz="0 0 0"/>
      <mass value="9.0"/>
      <inertia ixx="0.01" ixy="0.01" ixz="0.01" iyy="0.01" iyz="0.401" izz="0.401"/>
    </inertial>
  </link>
  <!-- left arm joint -->
  <joint name="base_to_left_arm_base" type="fixed">
    <origin rpy="0 0 0" xyz="0.14142 0.14142 0.2475"/>
    <parent link="base_link"/>
    <child link="left_arm_base_link"/>
  </joint>
  <!-- foot -->
  <!-- <xacro:include filename="$(find moonbot_description)/urdf/yonaka_0722/common_gazebo.xacro" /> -->
  <!-- base link -->
  <link name="left_arm_base_link">
    <inertial>
      <mass value="0.001"/>
      <inertia ixx="0.000000" ixy="0.000000" ixz="0.000000" iyy="0.000000" iyz="0.000000" izz="0.000000"/>
    </inertial>
  </link>
  <!-- joint 1 -->
  <joint name="left_arm_joint1" type="revolute">
    <axis rpy="0 0 0" xyz="0 0 1"/>
    <limit effort="1000.0" lower="-0.2617993877991494" upper="3.141592653589793" velocity="0.5235987755982988"/>
    <origin rpy="0 0 0" xyz="0 0.0 0.0"/>
    <parent link="left_arm_base_link"/>
    <child link="left_arm_link1"/>
  </joint>
  <link name="left_arm_link1">
    <visual>
      <origin rpy="0 0 0" xyz="0 0 0"/>
      <material name="White"/>
      <geometry>
        <mesh filename="package://moonbot_description/meshesY/M_Assy_arm1.STL" scale="0.001 0.001 0.001"/>
      </geometry>
    </visual>
    <collision>
      <origin rpy="0 0 0" xyz="0 0 0"/>
      <geometry>
        <mesh filename="package://moonbot_description/meshesY/M_Assy_arm1.STL" scale="0.001 0.001 0.001"/>
      </geometry>
    </collision>
    <inertial>
      <origin rpy="0 0 0" xyz="0 0 0"/>
      <mass value="3.55"/>
      <inertia ixx="0.1" ixy="0.1" ixz="0.1" iyy="0.1" iyz="0.1" izz="0.1"/>
    </inertial>
  </link>
  <!-- joint 2 -->
  <joint name="left_arm_joint2" type="revolute">
    <axis rpy="0 0 0" xyz="0 1 0"/>
    <limit effort="1000.0" lower="-2.6179938779914944" upper="2.6179938779914944" velocity="0.5235987755982988"/>
    <origin rpy="0 0 0" xyz="0.09 0.0 -0.0"/>
    <parent link="left_arm_link1"/>
    <child link="left_arm_link2"/>
  </joint>
  <link name="left_arm_link2">
    <visual>
      <origin rpy="0 0 0" xyz="0 0 0"/>
      <material name="White"/>
      <geometry>
        <mesh filename="package://moonbot_description/meshesY/M_Assy_arm2.STL" scale="0.001 0.001 0.001"/>
      </geometry>
    </visual>
    <collision>
      <origin rpy="0 0 0" xyz="0 0 0"/>
      <geometry>
        <mesh filename="package://moonbot_description/meshesY/M_Assy_arm2.STL" scale="0.001 0.001 0.001"/>
      </geometry>
    </collision>
    <inertial>
      <origin rpy="0 0 0" xyz="0 0 0"/>
      <mass value="0.99"/>
      <inertia ixx="0.1" ixy="0.1" ixz="0.1" iyy="0.1" iyz="0.1" izz="0.1"/>
    </inertial>
  </link>
  <!-- joint 3 -->
  <joint name="left_arm_joint3" type="revolute">
    <axis rpy="0 0 0" xyz="0 1 0"/>
    <limit effort="1000.0" lower="-2.6179938779914944" upper="2.6179938779914944" velocity="0.5235987755982988"/>
    <origin rpy="0 0 0" xyz="0.0 0.0 0.28"/>
    <parent link="left_arm_link2"/>
    <child link="left_arm_link3"/>
  </joint>
  <link name="left_arm_link3">
    <visual>
      <origin rpy="0 0 0" xyz="0 0 0"/>
      <material name="White"/>
      <geometry>
        <mesh filename="package://moonbot_description/meshesY/M_Assy_arm3.STL" scale="0.001 0.001 0.001"/>
      </geometry>
    </visual>
    <collision>
      <origin rpy="0 0 0" xyz="0 0 0"/>
      <geometry>
        <mesh filename="package://moonbot_description/meshesY/M_Assy_arm3.STL" scale="0.001 0.001 0.001"/>
      </geometry>
    </collision>
    <inertial>
      <origin rpy="0 0 0" xyz="0 0 0"/>
      <mass value="0.43"/>
      <inertia ixx="0.1" ixy="0.1" ixz="0.1" iyy="0.1" iyz="0.1" izz="0.1"/>
    </inertial>
  </link>
  <!-- joint 4 -->
  <joint name="left_arm_joint4" type="revolute">
    <axis rpy="0 0 0" xyz="0 0 1"/>
    <limit effort="1000.0" lower="-6.283185307179586" upper="6.283185307179586" velocity="0.5235987755982988"/>
    <origin rpy="0 0 0" xyz="0.0 0.0 0.33"/>
    <parent link="left_arm_link3"/>
    <child link="left_arm_link4"/>
  </joint>
  <link name="left_arm_link4">
    <visual>
      <origin rpy="0 0 0" xyz="0 0 0"/>
      <material name="White"/>
      <geometry>
        <mesh filename="package://moonbot_description/meshesY/HAND_L1.STL" scale="0.001 0.001 0.001"/>
      </geometry>
    </visual>
    <collision>
      <origin rpy="0 0 0" xyz="0 0 0"/>
      <geometry>
        <mesh filename="package://moonbot_description/meshesY/HAND_L1.STL" scale="0.001 0.001 0.001"/>
      </geometry>
    </collision>
    <inertial>
      <origin rpy="0 0 0" xyz="0 0 0"/>
      <mass value="0.6"/>
      <inertia ixx="0.1" ixy="0.1" ixz="0.1" iyy="0.1" iyz="0.1" izz="0.1"/>
    </inertial>
  </link>
  <!-- joint 5 -->
  <joint name="left_arm_joint5" type="revolute">
    <axis rpy="0 0 0" xyz="0 1 0"/>
    <limit effort="1000.0" lower="-0.5235987755982988" upper="0.5235987755982988" velocity="0.5235987755982988"/>
    <origin rpy="0 0 0" xyz="0.0 0.0 0.165"/>
    <parent link="left_arm_link4"/>
    <child link="left_arm_link5"/>
  </joint>
  <link name="left_arm_link5">
    <visual>
      <origin rpy="0 0 0" xyz="0 0 -0.165"/>
      <material name="White"/>
      <geometry>
        <mesh filename="package://moonbot_description/meshesY/HAND_L2.STL" scale="0.001 0.001 0.001"/>
      </geometry>
    </visual>
    <collision>
      <origin rpy="0 0 0" xyz="0 0 -0.165"/>
      <geometry>
        <mesh filename="package://moonbot_description/meshesY/HAND_L2.STL" scale="0.001 0.001 0.001"/>
      </geometry>
    </collision>
    <inertial>
      <origin rpy="0 0 0" xyz="0 0 -0.165"/>
      <mass value="0.08"/>
      <inertia ixx="0.1" ixy="0.1" ixz="0.1" iyy="0.1" iyz="0.1" izz="0.1"/>
    </inertial>
  </link>
  <!-- joint 6 -->
  <joint name="left_arm_joint6" type="revolute">
    <axis rpy="0 0 0" xyz="1 0 0"/>
    <limit effort="1000.0" lower="-1.5707963267948966" upper="1.5707963267948966" velocity="0.5235987755982988"/>
    <origin rpy="0 0 0" xyz="0.0 0.0 0.0"/>
    <parent link="left_arm_link5"/>
    <child link="left_arm_link6"/>
  </joint>
  <link name="left_arm_link6">
    <visual>
      <origin rpy="0 0 0" xyz="0 0 -0.165"/>
      <material name="White"/>
      <geometry>
        <mesh filename="package://moonbot_description/meshesY/HAND_L3.STL" scale="0.001 0.001 0.001"/>
      </geometry>
    </visual>
    <collision>
      <origin rpy="0 0 0" xyz="0 0 -0.165"/>
      <geometry>
        <mesh filename="package://moonbot_description/meshesY/HAND_L3.STL" scale="0.001 0.001 0.001"/>
      </geometry>
    </collision>
    <inertial>
      <origin rpy="0 0 0" xyz="0 0 -0.165"/>
      <mass value="0.08"/>
      <inertia ixx="0.1" ixy="0.1" ixz="0.1" iyy="0.1" iyz="0.1" izz="0.1"/>
    </inertial>
  </link>
  <!-- finger link -->
  <!-- <xacro:if value="${prefix == 'left_'}">
      <xacro:link name="${prefix}finger_link1" material="White" mesh="HAND_L4.STL" mass="0.01" ixx="0.1" ixy="0.1" ixz="0.1" iyy="0.1" iyz="0.1" izz="0.1" xyz='0 0 -0.165'/>
      <xacro:link name="${prefix}finger_link2" material="White" mesh="HAND_L5.STL" mass="0.01" ixx="0.1" ixy="0.1" ixz="0.1" iyy="0.1" iyz="0.1" izz="0.1" xyz='0 0 -0.165'/>
      <xacro:link name="${prefix}finger_link3" material="White" mesh="HAND_L6.STL" mass="0.01" ixx="0.1" ixy="0.1" ixz="0.1" iyy="0.1" iyz="0.1" izz="0.1" xyz='0 0 -0.165'/>
      <xacro:link name="${prefix}finger_link4" material="White" mesh="HAND_L7.STL" mass="0.01" ixx="0.1" ixy="0.1" ixz="0.1" iyy="0.1" iyz="0.1" izz="0.1" xyz='0 0 -0.165'/>
      <xacro:link name="${prefix}finger_link5" material="White" mesh="HAND_L8.STL" mass="0.01" ixx="0.1" ixy="0.1" ixz="0.1" iyy="0.1" iyz="0.1" izz="0.1" xyz='0 0 -0.165'/>
    </xacro:if>
    <xacro:if value="${prefix == 'right_'}">
      <xacro:link name="${prefix}finger_link1" material="White" mesh="HAND_R4.STL" mass="0.01" ixx="0.1" ixy="0.1" ixz="0.1" iyy="0.1" iyz="0.1" izz="0.1" xyz='0 0 -0.165'/>
      <xacro:link name="${prefix}finger_link2" material="White" mesh="HAND_R5.STL" mass="0.01" ixx="0.1" ixy="0.1" ixz="0.1" iyy="0.1" iyz="0.1" izz="0.1" xyz='0 0 -0.165'/>
      <xacro:link name="${prefix}finger_link3" material="White" mesh="HAND_R6.STL" mass="0.01" ixx="0.1" ixy="0.1" ixz="0.1" iyy="0.1" iyz="0.1" izz="0.1" xyz='0 0 -0.165'/>
      <xacro:link name="${prefix}finger_link4" material="White" mesh="HAND_R7.STL" mass="0.01" ixx="0.1" ixy="0.1" ixz="0.1" iyy="0.1" iyz="0.1" izz="0.1" xyz='0 0 -0.165'/>
      <xacro:link name="${prefix}finger_link5" material="White" mesh="HAND_R8.STL" mass="0.01" ixx="0.1" ixy="0.1" ixz="0.1" iyy="0.1" iyz="0.1" izz="0.1" xyz='0 0 -0.165'/>
    </xacro:if> -->
  <!-- finger joint -->
  <!-- <joint name="${prefix}finger_joint1" type="fixed">
      <origin xyz="0.0 0.0 0.0" rpy="0 0 0"/>
      <parent link="${prefix}arm_link6"/>
      <child link="${prefix}finger_link1"/>
    </joint> -->
  <!-- <joint name="${prefix}finger_joint2" type="fixed">
      <origin xyz="0.0 0.0 0.0" rpy="0 0 0"/>
      <parent link="${prefix}arm_link6"/>
      <child link="${prefix}finger_link2"/>
    </joint> -->
  <!-- <joint name="${prefix}finger_joint3" type="fixed">
      <origin xyz="0.0 0.0 0.0" rpy="0 0 0"/>
      <parent link="${prefix}arm_link6"/>
      <child link="${prefix}finger_link3"/>
    </joint> -->
  <!-- <joint name="${prefix}finger_joint4" type="fixed">
      <origin xyz="0.0 0.0 0.0" rpy="0 0 0"/>
      <parent link="${prefix}arm_link6"/>
      <child link="${prefix}finger_link4"/>
    </joint> -->
  <!-- <joint name="${prefix}finger_joint5" type="fixed">
      <origin xyz="0.0 0.0 0.0" rpy="0 0 0"/>
      <parent link="${prefix}arm_link6"/>
      <child link="${prefix}finger_link5"/>
    </joint>  -->
  <!-- <xacro:transmission joint="${prefix}arm_joint1"/>
    <xacro:transmission joint="${prefix}arm_joint2"/>
    <xacro:transmission joint="${prefix}arm_joint3"/>
    <xacro:transmission joint="${prefix}arm_joint4"/> -->
  <!-- right arm joint -->
  <joint name="base_to_right_arm_base" type="fixed">
    <origin rpy="0 0 -0" xyz="0.14142 -0.14142 0.2475"/>
    <parent link="base_link"/>
    <child link="right_arm_base_link"/>
  </joint>
  <!-- foot -->
  <!-- <xacro:include filename="$(find moonbot_description)/urdf/yonaka_0722/common_gazebo.xacro" /> -->
  <!-- base link -->
  <link name="right_arm_base_link">
    <inertial>
      <mass value="0.001"/>
      <inertia ixx="0.000000" ixy="0.000000" ixz="0.000000" iyy="0.000000" iyz="0.000000" izz="0.000000"/>
    </inertial>
  </link>
  <!-- joint 1 -->
  <joint name="right_arm_joint1" type="revolute">
    <axis rpy="0 0 0" xyz="0 0 1"/>
    <limit effort="1000.0" lower="-3.141592653589793" upper="0.2617993877991494" velocity="-0.5235987755982988"/>
    <origin rpy="0 0 0" xyz="0 0.0 0.0"/>
    <parent link="right_arm_base_link"/>
    <child link="right_arm_link1"/>
  </joint>
  <link name="right_arm_link1">
    <visual>
      <origin rpy="0 0 0" xyz="0 0 0"/>
      <material name="White"/>
      <geometry>
        <mesh filename="package://moonbot_description/meshesY/M_Assy_arm1.STL" scale="0.001 0.001 0.001"/>
      </geometry>
    </visual>
    <collision>
      <origin rpy="0 0 0" xyz="0 0 0"/>
      <geometry>
        <mesh filename="package://moonbot_description/meshesY/M_Assy_arm1.STL" scale="0.001 0.001 0.001"/>
      </geometry>
    </collision>
    <inertial>
      <origin rpy="0 0 0" xyz="0 0 0"/>
      <mass value="3.55"/>
      <inertia ixx="0.1" ixy="0.1" ixz="0.1" iyy="0.1" iyz="0.1" izz="0.1"/>
    </inertial>
  </link>
  <!-- joint 2 -->
  <joint name="right_arm_joint2" type="revolute">
    <axis rpy="0 0 0" xyz="0 1 0"/>
    <limit effort="1000.0" lower="-2.6179938779914944" upper="2.6179938779914944" velocity="0.5235987755982988"/>
    <origin rpy="0 0 0" xyz="0.09 0.0 -0.0"/>
    <parent link="right_arm_link1"/>
    <child link="right_arm_link2"/>
  </joint>
  <link name="right_arm_link2">
    <visual>
      <origin rpy="0 0 0" xyz="0 0 0"/>
      <material name="White"/>
      <geometry>
        <mesh filename="package://moonbot_description/meshesY/M_Assy_arm2.STL" scale="0.001 0.001 0.001"/>
      </geometry>
    </visual>
    <collision>
      <origin rpy="0 0 0" xyz="0 0 0"/>
      <geometry>
        <mesh filename="package://moonbot_description/meshesY/M_Assy_arm2.STL" scale="0.001 0.001 0.001"/>
      </geometry>
    </collision>
    <inertial>
      <origin rpy="0 0 0" xyz="0 0 0"/>
      <mass value="0.99"/>
      <inertia ixx="0.1" ixy="0.1" ixz="0.1" iyy="0.1" iyz="0.1" izz="0.1"/>
    </inertial>
  </link>
  <!-- joint 3 -->
  <joint name="right_arm_joint3" type="revolute">
    <axis rpy="0 0 0" xyz="0 1 0"/>
    <limit effort="1000.0" lower="-2.6179938779914944" upper="2.6179938779914944" velocity="0.5235987755982988"/>
    <origin rpy="0 0 0" xyz="0.0 0.0 0.28"/>
    <parent link="right_arm_link2"/>
    <child link="right_arm_link3"/>
  </joint>
  <link name="right_arm_link3">
    <visual>
      <origin rpy="0 0 0" xyz="0 0 0"/>
      <material name="White"/>
      <geometry>
        <mesh filename="package://moonbot_description/meshesY/M_Assy_arm3.STL" scale="0.001 0.001 0.001"/>
      </geometry>
    </visual>
    <collision>
      <origin rpy="0 0 0" xyz="0 0 0"/>
      <geometry>
        <mesh filename="package://moonbot_description/meshesY/M_Assy_arm3.STL" scale="0.001 0.001 0.001"/>
      </geometry>
    </collision>
    <inertial>
      <origin rpy="0 0 0" xyz="0 0 0"/>
      <mass value="0.43"/>
      <inertia ixx="0.1" ixy="0.1" ixz="0.1" iyy="0.1" iyz="0.1" izz="0.1"/>
    </inertial>
  </link>
  <!-- joint 4 -->
  <joint name="right_arm_joint4" type="revolute">
    <axis rpy="0 0 0" xyz="0 0 1"/>
    <limit effort="1000.0" lower="-6.283185307179586" upper="6.283185307179586" velocity="0.5235987755982988"/>
    <origin rpy="0 0 0" xyz="0.0 0.0 0.33"/>
    <parent link="right_arm_link3"/>
    <child link="right_arm_link4"/>
  </joint>
  <link name="right_arm_link4">
    <visual>
      <origin rpy="0 0 0" xyz="0 0 0"/>
      <material name="White"/>
      <geometry>
        <mesh filename="package://moonbot_description/meshesY/HAND_R1.STL" scale="0.001 0.001 0.001"/>
      </geometry>
    </visual>
    <collision>
      <origin rpy="0 0 0" xyz="0 0 0"/>
      <geometry>
        <mesh filename="package://moonbot_description/meshesY/HAND_R1.STL" scale="0.001 0.001 0.001"/>
      </geometry>
    </collision>
    <inertial>
      <origin rpy="0 0 0" xyz="0 0 0"/>
      <mass value="0.6"/>
      <inertia ixx="0.1" ixy="0.1" ixz="0.1" iyy="0.1" iyz="0.1" izz="0.1"/>
    </inertial>
  </link>
  <!-- joint 5 -->
  <joint name="right_arm_joint5" type="revolute">
    <axis rpy="0 0 0" xyz="0 1 0"/>
    <limit effort="1000.0" lower="-0.5235987755982988" upper="0.5235987755982988" velocity="0.5235987755982988"/>
    <origin rpy="0 0 0" xyz="0.0 0.0 0.165"/>
    <parent link="right_arm_link4"/>
    <child link="right_arm_link5"/>
  </joint>
  <link name="right_arm_link5">
    <visual>
      <origin rpy="0 0 0" xyz="0 0 -0.165"/>
      <material name="White"/>
      <geometry>
        <mesh filename="package://moonbot_description/meshesY/HAND_R2.STL" scale="0.001 0.001 0.001"/>
      </geometry>
    </visual>
    <collision>
      <origin rpy="0 0 0" xyz="0 0 -0.165"/>
      <geometry>
        <mesh filename="package://moonbot_description/meshesY/HAND_R2.STL" scale="0.001 0.001 0.001"/>
      </geometry>
    </collision>
    <inertial>
      <origin rpy="0 0 0" xyz="0 0 -0.165"/>
      <mass value="0.08"/>
      <inertia ixx="0.1" ixy="0.1" ixz="0.1" iyy="0.1" iyz="0.1" izz="0.1"/>
    </inertial>
  </link>
  <!-- joint 6 -->
  <joint name="right_arm_joint6" type="revolute">
    <axis rpy="0 0 0" xyz="1 0 0"/>
    <limit effort="1000.0" lower="-1.5707963267948966" upper="1.5707963267948966" velocity="0.5235987755982988"/>
    <origin rpy="0 0 0" xyz="0.0 0.0 0.0"/>
    <parent link="right_arm_link5"/>
    <child link="right_arm_link6"/>
  </joint>
  <link name="right_arm_link6">
    <visual>
      <origin rpy="0 0 0" xyz="0 0 -0.165"/>
      <material name="White"/>
      <geometry>
        <mesh filename="package://moonbot_description/meshesY/HAND_R3.STL" scale="0.001 0.001 0.001"/>
      </geometry>
    </visual>
    <collision>
      <origin rpy="0 0 0" xyz="0 0 -0.165"/>
      <geometry>
        <mesh filename="package://moonbot_description/meshesY/HAND_R3.STL" scale="0.001 0.001 0.001"/>
      </geometry>
    </collision>
    <inertial>
      <origin rpy="0 0 0" xyz="0 0 -0.165"/>
      <mass value="0.08"/>
      <inertia ixx="0.1" ixy="0.1" ixz="0.1" iyy="0.1" iyz="0.1" izz="0.1"/>
    </inertial>
  </link>
  <!-- finger link -->
  <!-- <xacro:if value="${prefix == 'left_'}">
      <xacro:link name="${prefix}finger_link1" material="White" mesh="HAND_L4.STL" mass="0.01" ixx="0.1" ixy="0.1" ixz="0.1" iyy="0.1" iyz="0.1" izz="0.1" xyz='0 0 -0.165'/>
      <xacro:link name="${prefix}finger_link2" material="White" mesh="HAND_L5.STL" mass="0.01" ixx="0.1" ixy="0.1" ixz="0.1" iyy="0.1" iyz="0.1" izz="0.1" xyz='0 0 -0.165'/>
      <xacro:link name="${prefix}finger_link3" material="White" mesh="HAND_L6.STL" mass="0.01" ixx="0.1" ixy="0.1" ixz="0.1" iyy="0.1" iyz="0.1" izz="0.1" xyz='0 0 -0.165'/>
      <xacro:link name="${prefix}finger_link4" material="White" mesh="HAND_L7.STL" mass="0.01" ixx="0.1" ixy="0.1" ixz="0.1" iyy="0.1" iyz="0.1" izz="0.1" xyz='0 0 -0.165'/>
      <xacro:link name="${prefix}finger_link5" material="White" mesh="HAND_L8.STL" mass="0.01" ixx="0.1" ixy="0.1" ixz="0.1" iyy="0.1" iyz="0.1" izz="0.1" xyz='0 0 -0.165'/>
    </xacro:if>
    <xacro:if value="${prefix == 'right_'}">
      <xacro:link name="${prefix}finger_link1" material="White" mesh="HAND_R4.STL" mass="0.01" ixx="0.1" ixy="0.1" ixz="0.1" iyy="0.1" iyz="0.1" izz="0.1" xyz='0 0 -0.165'/>
      <xacro:link name="${prefix}finger_link2" material="White" mesh="HAND_R5.STL" mass="0.01" ixx="0.1" ixy="0.1" ixz="0.1" iyy="0.1" iyz="0.1" izz="0.1" xyz='0 0 -0.165'/>
      <xacro:link name="${prefix}finger_link3" material="White" mesh="HAND_R6.STL" mass="0.01" ixx="0.1" ixy="0.1" ixz="0.1" iyy="0.1" iyz="0.1" izz="0.1" xyz='0 0 -0.165'/>
      <xacro:link name="${prefix}finger_link4" material="White" mesh="HAND_R7.STL" mass="0.01" ixx="0.1" ixy="0.1" ixz="0.1" iyy="0.1" iyz="0.1" izz="0.1" xyz='0 0 -0.165'/>
      <xacro:link name="${prefix}finger_link5" material="White" mesh="HAND_R8.STL" mass="0.01" ixx="0.1" ixy="0.1" ixz="0.1" iyy="0.1" iyz="0.1" izz="0.1" xyz='0 0 -0.165'/>
    </xacro:if> -->
  <!-- finger joint -->
  <!-- <joint name="${prefix}finger_joint1" type="fixed">
      <origin xyz="0.0 0.0 0.0" rpy="0 0 0"/>
      <parent link="${prefix}arm_link6"/>
      <child link="${prefix}finger_link1"/>
    </joint> -->
  <!-- <joint name="${prefix}finger_joint2" type="fixed">
      <origin xyz="0.0 0.0 0.0" rpy="0 0 0"/>
      <parent link="${prefix}arm_link6"/>
      <child link="${prefix}finger_link2"/>
    </joint> -->
  <!-- <joint name="${prefix}finger_joint3" type="fixed">
      <origin xyz="0.0 0.0 0.0" rpy="0 0 0"/>
      <parent link="${prefix}arm_link6"/>
      <child link="${prefix}finger_link3"/>
    </joint> -->
  <!-- <joint name="${prefix}finger_joint4" type="fixed">
      <origin xyz="0.0 0.0 0.0" rpy="0 0 0"/>
      <parent link="${prefix}arm_link6"/>
      <child link="${prefix}finger_link4"/>
    </joint> -->
  <!-- <joint name="${prefix}finger_joint5" type="fixed">
      <origin xyz="0.0 0.0 0.0" rpy="0 0 0"/>
      <parent link="${prefix}arm_link6"/>
      <child link="${prefix}finger_link5"/>
    </joint>  -->
  <!-- <xacro:transmission joint="${prefix}arm_joint1"/>
    <xacro:transmission joint="${prefix}arm_joint2"/>
    <xacro:transmission joint="${prefix}arm_joint3"/>
    <xacro:transmission joint="${prefix}arm_joint4"/> -->
  <!-- forward left leg joint -->
  <joint name="base_to_f_left_leg_base" type="fixed">
    <origin rpy="0 0 0.7854" xyz="0.14142 0.14142 0.0395"/>
    <parent link="base_link"/>
    <child link="f_left_leg_base_link"/>
  </joint>
  <!-- foot -->
  <!-- <xacro:include filename="$(find moonbot_description)/urdf/yonaka_0722/common_gazebo.xacro" /> -->
  <!-- base link -->
  <link name="f_left_leg_base_link">
    <inertial>
      <mass value="0.001"/>
      <inertia ixx="0.000000" ixy="0.000000" ixz="0.000000" iyy="0.000000" iyz="0.000000" izz="0.000000"/>
    </inertial>
  </link>
  <!-- joint 1 -->
  <joint name="f_left_leg_joint1" type="revolute">
    <axis rpy="0 0 0" xyz="0 0 1"/>
    <limit effort="1000.0" lower="-1.5707963267948966" upper="1.5707963267948966" velocity="3.141592653589793"/>
    <origin rpy="0 0 0" xyz="0 0.0 0.0"/>
    <parent link="f_left_leg_base_link"/>
    <child link="f_left_leg_link1"/>
  </joint>
  <link name="f_left_leg_link1">
    <visual>
      <origin rpy="0 0 0" xyz="0 0 0"/>
      <material name="White"/>
      <geometry>
        <mesh filename="package://moonbot_description/meshesY/M_Assy1.STL" scale="0.001 0.001 0.001"/>
      </geometry>
    </visual>
    <collision>
      <origin rpy="0 0 0" xyz="0 0 0"/>
      <geometry>
        <mesh filename="package://moonbot_description/meshesY/M_Assy1.STL" scale="0.001 0.001 0.001"/>
      </geometry>
    </collision>
    <inertial>
      <origin rpy="0 0 0" xyz="0 0 0"/>
      <mass value="3.55"/>
      <inertia ixx="0.1" ixy="0.1" ixz="0.1" iyy="0.1" iyz="0.1" izz="0.1"/>
    </inertial>
  </link>
  <!-- joint 2 -->
  <joint name="f_left_leg_joint2" type="revolute">
    <axis rpy="0 0 0" xyz="0 1 0"/>
    <limit effort="1000.0" lower="-2.6179938779914944" upper="0.17453292519943295" velocity="3.141592653589793"/>
    <origin rpy="0 0 0" xyz="0.09 0.0 -0.0"/>
    <parent link="f_left_leg_link1"/>
    <child link="f_left_leg_link2"/>
  </joint>
  <link name="f_left_leg_link2">
    <visual>
      <origin rpy="0 0 0" xyz="0 0 0"/>
      <material name="White"/>
      <geometry>
        <mesh filename="package://moonbot_description/meshesY/M_Assy2.STL" scale="0.001 0.001 0.001"/>
      </geometry>
    </visual>
    <collision>
      <origin rpy="0 0 0" xyz="0 0 0"/>
      <geometry>
        <mesh filename="package://moonbot_description/meshesY/M_Assy2.STL" scale="0.001 0.001 0.001"/>
      </geometry>
    </collision>
    <inertial>
      <origin rpy="0 0 0" xyz="0 0 0"/>
      <mass value="0.99"/>
      <inertia ixx="0.1" ixy="0.1" ixz="0.1" iyy="0.1" iyz="0.1" izz="0.1"/>
    </inertial>
  </link>
  <!-- joint 3 -->
  <joint name="f_left_leg_joint3" type="revolute">
    <axis rpy="0 0 0" xyz="0 1 0"/>
    <limit effort="1000.0" lower="-2.792526803190927" upper="2.0943951023931953" velocity="3.141592653589793"/>
    <origin rpy="0 0 0" xyz="0.0 0 -0.28"/>
    <parent link="f_left_leg_link2"/>
    <child link="f_left_leg_link3"/>
  </joint>
  <link name="f_left_leg_link3">
    <visual>
      <origin rpy="0 0 0" xyz="0 0 0"/>
      <material name="White"/>
      <geometry>
        <mesh filename="package://moonbot_description/meshesY/M_Assy3.STL" scale="0.001 0.001 0.001"/>
      </geometry>
    </visual>
    <collision>
      <origin rpy="0 0 0" xyz="0 0 0"/>
      <geometry>
        <mesh filename="package://moonbot_description/meshesY/M_Assy3.STL" scale="0.001 0.001 0.001"/>
      </geometry>
    </collision>
    <inertial>
      <origin rpy="0 0 0" xyz="0 0 0"/>
      <mass value="0.43"/>
      <inertia ixx="0.1" ixy="0.1" ixz="0.1" iyy="0.1" iyz="0.1" izz="0.1"/>
    </inertial>
  </link>
  <!-- <xacro:transmission joint="${prefix}leg_joint1"/>
    <xacro:transmission joint="${prefix}leg_joint2"/>
    <xacro:transmission joint="${prefix}leg_joint3"/> -->
  <!-- forward right leg joint -->
  <joint name="base_to_f_right_leg_base" type="fixed">
    <origin rpy="0 0 -0.7854" xyz="0.14142 -0.14142 0.0395"/>
    <parent link="base_link"/>
    <child link="f_right_leg_base_link"/>
  </joint>
  <!-- foot -->
  <!-- <xacro:include filename="$(find moonbot_description)/urdf/yonaka_0722/common_gazebo.xacro" /> -->
  <!-- base link -->
  <link name="f_right_leg_base_link">
    <inertial>
      <mass value="0.001"/>
      <inertia ixx="0.000000" ixy="0.000000" ixz="0.000000" iyy="0.000000" iyz="0.000000" izz="0.000000"/>
    </inertial>
  </link>
  <!-- joint 1 -->
  <joint name="f_right_leg_joint1" type="revolute">
    <axis rpy="0 0 0" xyz="0 0 1"/>
    <limit effort="1000.0" lower="-1.5707963267948966" upper="1.5707963267948966" velocity="3.141592653589793"/>
    <origin rpy="0 0 0" xyz="0 0.0 0.0"/>
    <parent link="f_right_leg_base_link"/>
    <child link="f_right_leg_link1"/>
  </joint>
  <link name="f_right_leg_link1">
    <visual>
      <origin rpy="0 0 0" xyz="0 0 0"/>
      <material name="White"/>
      <geometry>
        <mesh filename="package://moonbot_description/meshesY/M_Assy1.STL" scale="0.001 0.001 0.001"/>
      </geometry>
    </visual>
    <collision>
      <origin rpy="0 0 0" xyz="0 0 0"/>
      <geometry>
        <mesh filename="package://moonbot_description/meshesY/M_Assy1.STL" scale="0.001 0.001 0.001"/>
      </geometry>
    </collision>
    <inertial>
      <origin rpy="0 0 0" xyz="0 0 0"/>
      <mass value="3.55"/>
      <inertia ixx="0.1" ixy="0.1" ixz="0.1" iyy="0.1" iyz="0.1" izz="0.1"/>
    </inertial>
  </link>
  <!-- joint 2 -->
  <joint name="f_right_leg_joint2" type="revolute">
    <axis rpy="0 0 0" xyz="0 1 0"/>
    <limit effort="1000.0" lower="-2.6179938779914944" upper="0.17453292519943295" velocity="3.141592653589793"/>
    <origin rpy="0 0 0" xyz="0.09 0.0 -0.0"/>
    <parent link="f_right_leg_link1"/>
    <child link="f_right_leg_link2"/>
  </joint>
  <link name="f_right_leg_link2">
    <visual>
      <origin rpy="0 0 0" xyz="0 0 0"/>
      <material name="White"/>
      <geometry>
        <mesh filename="package://moonbot_description/meshesY/M_Assy2.STL" scale="0.001 0.001 0.001"/>
      </geometry>
    </visual>
    <collision>
      <origin rpy="0 0 0" xyz="0 0 0"/>
      <geometry>
        <mesh filename="package://moonbot_description/meshesY/M_Assy2.STL" scale="0.001 0.001 0.001"/>
      </geometry>
    </collision>
    <inertial>
      <origin rpy="0 0 0" xyz="0 0 0"/>
      <mass value="0.99"/>
      <inertia ixx="0.1" ixy="0.1" ixz="0.1" iyy="0.1" iyz="0.1" izz="0.1"/>
    </inertial>
  </link>
  <!-- joint 3 -->
  <joint name="f_right_leg_joint3" type="revolute">
    <axis rpy="0 0 0" xyz="0 1 0"/>
    <limit effort="1000.0" lower="-2.792526803190927" upper="2.0943951023931953" velocity="3.141592653589793"/>
    <origin rpy="0 0 0" xyz="0.0 0 -0.28"/>
    <parent link="f_right_leg_link2"/>
    <child link="f_right_leg_link3"/>
  </joint>
  <link name="f_right_leg_link3">
    <visual>
      <origin rpy="0 0 0" xyz="0 0 0"/>
      <material name="White"/>
      <geometry>
        <mesh filename="package://moonbot_description/meshesY/M_Assy3.STL" scale="0.001 0.001 0.001"/>
      </geometry>
    </visual>
    <collision>
      <origin rpy="0 0 0" xyz="0 0 0"/>
      <geometry>
        <mesh filename="package://moonbot_description/meshesY/M_Assy3.STL" scale="0.001 0.001 0.001"/>
      </geometry>
    </collision>
    <inertial>
      <origin rpy="0 0 0" xyz="0 0 0"/>
      <mass value="0.43"/>
      <inertia ixx="0.1" ixy="0.1" ixz="0.1" iyy="0.1" iyz="0.1" izz="0.1"/>
    </inertial>
  </link>
  <!-- <xacro:transmission joint="${prefix}leg_joint1"/>
    <xacro:transmission joint="${prefix}leg_joint2"/>
    <xacro:transmission joint="${prefix}leg_joint3"/> -->
  <!-- back left leg joint -->
  <joint name="base_to_b_left_leg_base" type="fixed">
    <origin rpy="0 0 2.3562" xyz="-0.14142 0.14142 0.0395"/>
    <parent link="base_link"/>
    <child link="b_left_leg_base_link"/>
  </joint>
  <!-- foot -->
  <!-- <xacro:include filename="$(find moonbot_description)/urdf/yonaka_0722/common_gazebo.xacro" /> -->
  <!-- base link -->
  <link name="b_left_leg_base_link">
    <inertial>
      <mass value="0.001"/>
      <inertia ixx="0.000000" ixy="0.000000" ixz="0.000000" iyy="0.000000" iyz="0.000000" izz="0.000000"/>
    </inertial>
  </link>
  <!-- joint 1 -->
  <joint name="b_left_leg_joint1" type="revolute">
    <axis rpy="0 0 0" xyz="0 0 1"/>
    <limit effort="1000.0" lower="-1.5707963267948966" upper="1.5707963267948966" velocity="3.141592653589793"/>
    <origin rpy="0 0 0" xyz="0 0.0 0.0"/>
    <parent link="b_left_leg_base_link"/>
    <child link="b_left_leg_link1"/>
  </joint>
  <link name="b_left_leg_link1">
    <visual>
      <origin rpy="0 0 0" xyz="0 0 0"/>
      <material name="White"/>
      <geometry>
        <mesh filename="package://moonbot_description/meshesY/M_Assy1.STL" scale="0.001 0.001 0.001"/>
      </geometry>
    </visual>
    <collision>
      <origin rpy="0 0 0" xyz="0 0 0"/>
      <geometry>
        <mesh filename="package://moonbot_description/meshesY/M_Assy1.STL" scale="0.001 0.001 0.001"/>
      </geometry>
    </collision>
    <inertial>
      <origin rpy="0 0 0" xyz="0 0 0"/>
      <mass value="3.55"/>
      <inertia ixx="0.1" ixy="0.1" ixz="0.1" iyy="0.1" iyz="0.1" izz="0.1"/>
    </inertial>
  </link>
  <!-- joint 2 -->
  <joint name="b_left_leg_joint2" type="revolute">
    <axis rpy="0 0 0" xyz="0 1 0"/>
    <limit effort="1000.0" lower="-2.6179938779914944" upper="0.17453292519943295" velocity="3.141592653589793"/>
    <origin rpy="0 0 0" xyz="0.09 0.0 -0.0"/>
    <parent link="b_left_leg_link1"/>
    <child link="b_left_leg_link2"/>
  </joint>
  <link name="b_left_leg_link2">
    <visual>
      <origin rpy="0 0 0" xyz="0 0 0"/>
      <material name="White"/>
      <geometry>
        <mesh filename="package://moonbot_description/meshesY/M_Assy2.STL" scale="0.001 0.001 0.001"/>
      </geometry>
    </visual>
    <collision>
      <origin rpy="0 0 0" xyz="0 0 0"/>
      <geometry>
        <mesh filename="package://moonbot_description/meshesY/M_Assy2.STL" scale="0.001 0.001 0.001"/>
      </geometry>
    </collision>
    <inertial>
      <origin rpy="0 0 0" xyz="0 0 0"/>
      <mass value="0.99"/>
      <inertia ixx="0.1" ixy="0.1" ixz="0.1" iyy="0.1" iyz="0.1" izz="0.1"/>
    </inertial>
  </link>
  <!-- joint 3 -->
  <joint name="b_left_leg_joint3" type="revolute">
    <axis rpy="0 0 0" xyz="0 1 0"/>
    <limit effort="1000.0" lower="-2.792526803190927" upper="2.0943951023931953" velocity="3.141592653589793"/>
    <origin rpy="0 0 0" xyz="0.0 0 -0.28"/>
    <parent link="b_left_leg_link2"/>
    <child link="b_left_leg_link3"/>
  </joint>
  <link name="b_left_leg_link3">
    <visual>
      <origin rpy="0 0 0" xyz="0 0 0"/>
      <material name="White"/>
      <geometry>
        <mesh filename="package://moonbot_description/meshesY/M_Assy3.STL" scale="0.001 0.001 0.001"/>
      </geometry>
    </visual>
    <collision>
      <origin rpy="0 0 0" xyz="0 0 0"/>
      <geometry>
        <mesh filename="package://moonbot_description/meshesY/M_Assy3.STL" scale="0.001 0.001 0.001"/>
      </geometry>
    </collision>
    <inertial>
      <origin rpy="0 0 0" xyz="0 0 0"/>
      <mass value="0.43"/>
      <inertia ixx="0.1" ixy="0.1" ixz="0.1" iyy="0.1" iyz="0.1" izz="0.1"/>
    </inertial>
  </link>
  <!-- <xacro:transmission joint="${prefix}leg_joint1"/>
    <xacro:transmission joint="${prefix}leg_joint2"/>
    <xacro:transmission joint="${prefix}leg_joint3"/> -->
  <!-- back right leg joint -->
  <joint name="base_to_b_right_leg_base" type="fixed">
    <origin rpy="0 0 -2.3562" xyz="-0.14142 -0.14142 0.0395"/>
    <parent link="base_link"/>
    <child link="b_right_leg_base_link"/>
  </joint>
  <!-- foot -->
  <!-- <xacro:include filename="$(find moonbot_description)/urdf/yonaka_0722/common_gazebo.xacro" /> -->
  <!-- base link -->
  <link name="b_right_leg_base_link">
    <inertial>
      <mass value="0.001"/>
      <inertia ixx="0.000000" ixy="0.000000" ixz="0.000000" iyy="0.000000" iyz="0.000000" izz="0.000000"/>
    </inertial>
  </link>
  <!-- joint 1 -->
  <joint name="b_right_leg_joint1" type="revolute">
    <axis rpy="0 0 0" xyz="0 0 1"/>
    <limit effort="1000.0" lower="-1.5707963267948966" upper="1.5707963267948966" velocity="3.141592653589793"/>
    <origin rpy="0 0 0" xyz="0 0.0 0.0"/>
    <parent link="b_right_leg_base_link"/>
    <child link="b_right_leg_link1"/>
  </joint>
  <link name="b_right_leg_link1">
    <visual>
      <origin rpy="0 0 0" xyz="0 0 0"/>
      <material name="White"/>
      <geometry>
        <mesh filename="package://moonbot_description/meshesY/M_Assy1.STL" scale="0.001 0.001 0.001"/>
      </geometry>
    </visual>
    <collision>
      <origin rpy="0 0 0" xyz="0 0 0"/>
      <geometry>
        <mesh filename="package://moonbot_description/meshesY/M_Assy1.STL" scale="0.001 0.001 0.001"/>
      </geometry>
    </collision>
    <inertial>
      <origin rpy="0 0 0" xyz="0 0 0"/>
      <mass value="3.55"/>
      <inertia ixx="0.1" ixy="0.1" ixz="0.1" iyy="0.1" iyz="0.1" izz="0.1"/>
    </inertial>
  </link>
  <!-- joint 2 -->
  <joint name="b_right_leg_joint2" type="revolute">
    <axis rpy="0 0 0" xyz="0 1 0"/>
    <limit effort="1000.0" lower="-2.6179938779914944" upper="0.17453292519943295" velocity="3.141592653589793"/>
    <origin rpy="0 0 0" xyz="0.09 0.0 -0.0"/>
    <parent link="b_right_leg_link1"/>
    <child link="b_right_leg_link2"/>
  </joint>
  <link name="b_right_leg_link2">
    <visual>
      <origin rpy="0 0 0" xyz="0 0 0"/>
      <material name="White"/>
      <geometry>
        <mesh filename="package://moonbot_description/meshesY/M_Assy2.STL" scale="0.001 0.001 0.001"/>
      </geometry>
    </visual>
    <collision>
      <origin rpy="0 0 0" xyz="0 0 0"/>
      <geometry>
        <mesh filename="package://moonbot_description/meshesY/M_Assy2.STL" scale="0.001 0.001 0.001"/>
      </geometry>
    </collision>
    <inertial>
      <origin rpy="0 0 0" xyz="0 0 0"/>
      <mass value="0.99"/>
      <inertia ixx="0.1" ixy="0.1" ixz="0.1" iyy="0.1" iyz="0.1" izz="0.1"/>
    </inertial>
  </link>
  <!-- joint 3 -->
  <joint name="b_right_leg_joint3" type="revolute">
    <axis rpy="0 0 0" xyz="0 1 0"/>
    <limit effort="1000.0" lower="-2.792526803190927" upper="2.0943951023931953" velocity="3.141592653589793"/>
    <origin rpy="0 0 0" xyz="0.0 0 -0.28"/>
    <parent link="b_right_leg_link2"/>
    <child link="b_right_leg_link3"/>
  </joint>
  <link name="b_right_leg_link3">
    <visual>
      <origin rpy="0 0 0" xyz="0 0 0"/>
      <material name="White"/>
      <geometry>
        <mesh filename="package://moonbot_description/meshesY/M_Assy3.STL" scale="0.001 0.001 0.001"/>
      </geometry>
    </visual>
    <collision>
      <origin rpy="0 0 0" xyz="0 0 0"/>
      <geometry>
        <mesh filename="package://moonbot_description/meshesY/M_Assy3.STL" scale="0.001 0.001 0.001"/>
      </geometry>
    </collision>
    <inertial>
      <origin rpy="0 0 0" xyz="0 0 0"/>
      <mass value="0.43"/>
      <inertia ixx="0.1" ixy="0.1" ixz="0.1" iyy="0.1" iyz="0.1" izz="0.1"/>
    </inertial>
  </link>
  <!-- <xacro:transmission joint="${prefix}leg_joint1"/>
    <xacro:transmission joint="${prefix}leg_joint2"/>
    <xacro:transmission joint="${prefix}leg_joint3"/> -->
</robot>
